2019-10-24 15:36:33,425 INFO: FortuneSite startup [in /Users/nessad/Programming/fortunesite/fortunesite/__init__.py:49]
2019-10-24 15:41:35,924 ERROR: Exception on /edit_profile [POST] [in /Users/nessad/.virtualenvs/fortunesite/lib/python3.7/site-packages/flask/app.py:1891]
Traceback (most recent call last):
  File "/Users/nessad/.virtualenvs/fortunesite/lib/python3.7/site-packages/sqlalchemy/engine/base.py", line 1249, in _execute_context
    cursor, statement, parameters, context
  File "/Users/nessad/.virtualenvs/fortunesite/lib/python3.7/site-packages/sqlalchemy/engine/default.py", line 580, in do_execute
    cursor.execute(statement, parameters)
sqlite3.IntegrityError: UNIQUE constraint failed: user.username

The above exception was the direct cause of the following exception:

Traceback (most recent call last):
  File "/Users/nessad/.virtualenvs/fortunesite/lib/python3.7/site-packages/flask/app.py", line 2446, in wsgi_app
    response = self.full_dispatch_request()
  File "/Users/nessad/.virtualenvs/fortunesite/lib/python3.7/site-packages/flask/app.py", line 1951, in full_dispatch_request
    rv = self.handle_user_exception(e)
  File "/Users/nessad/.virtualenvs/fortunesite/lib/python3.7/site-packages/flask/app.py", line 1820, in handle_user_exception
    reraise(exc_type, exc_value, tb)
  File "/Users/nessad/.virtualenvs/fortunesite/lib/python3.7/site-packages/flask/_compat.py", line 39, in reraise
    raise value
  File "/Users/nessad/.virtualenvs/fortunesite/lib/python3.7/site-packages/flask/app.py", line 1949, in full_dispatch_request
    rv = self.dispatch_request()
  File "/Users/nessad/.virtualenvs/fortunesite/lib/python3.7/site-packages/flask/app.py", line 1935, in dispatch_request
    return self.view_functions[rule.endpoint](**req.view_args)
  File "/Users/nessad/.virtualenvs/fortunesite/lib/python3.7/site-packages/flask_login/utils.py", line 261, in decorated_view
    return func(*args, **kwargs)
  File "/Users/nessad/Programming/fortunesite/fortunesite/routes.py", line 98, in edit_profile
    db.session.commit()
  File "/Users/nessad/.virtualenvs/fortunesite/lib/python3.7/site-packages/sqlalchemy/orm/scoping.py", line 162, in do
    return getattr(self.registry(), name)(*args, **kwargs)
  File "/Users/nessad/.virtualenvs/fortunesite/lib/python3.7/site-packages/sqlalchemy/orm/session.py", line 1027, in commit
    self.transaction.commit()
  File "/Users/nessad/.virtualenvs/fortunesite/lib/python3.7/site-packages/sqlalchemy/orm/session.py", line 494, in commit
    self._prepare_impl()
  File "/Users/nessad/.virtualenvs/fortunesite/lib/python3.7/site-packages/sqlalchemy/orm/session.py", line 473, in _prepare_impl
    self.session.flush()
  File "/Users/nessad/.virtualenvs/fortunesite/lib/python3.7/site-packages/sqlalchemy/orm/session.py", line 2470, in flush
    self._flush(objects)
  File "/Users/nessad/.virtualenvs/fortunesite/lib/python3.7/site-packages/sqlalchemy/orm/session.py", line 2608, in _flush
    transaction.rollback(_capture_exception=True)
  File "/Users/nessad/.virtualenvs/fortunesite/lib/python3.7/site-packages/sqlalchemy/util/langhelpers.py", line 68, in __exit__
    compat.reraise(exc_type, exc_value, exc_tb)
  File "/Users/nessad/.virtualenvs/fortunesite/lib/python3.7/site-packages/sqlalchemy/util/compat.py", line 153, in reraise
    raise value
  File "/Users/nessad/.virtualenvs/fortunesite/lib/python3.7/site-packages/sqlalchemy/orm/session.py", line 2568, in _flush
    flush_context.execute()
  File "/Users/nessad/.virtualenvs/fortunesite/lib/python3.7/site-packages/sqlalchemy/orm/unitofwork.py", line 422, in execute
    rec.execute(self)
  File "/Users/nessad/.virtualenvs/fortunesite/lib/python3.7/site-packages/sqlalchemy/orm/unitofwork.py", line 589, in execute
    uow,
  File "/Users/nessad/.virtualenvs/fortunesite/lib/python3.7/site-packages/sqlalchemy/orm/persistence.py", line 236, in save_obj
    update,
  File "/Users/nessad/.virtualenvs/fortunesite/lib/python3.7/site-packages/sqlalchemy/orm/persistence.py", line 996, in _emit_update_statements
    statement, multiparams
  File "/Users/nessad/.virtualenvs/fortunesite/lib/python3.7/site-packages/sqlalchemy/engine/base.py", line 988, in execute
    return meth(self, multiparams, params)
  File "/Users/nessad/.virtualenvs/fortunesite/lib/python3.7/site-packages/sqlalchemy/sql/elements.py", line 287, in _execute_on_connection
    return connection._execute_clauseelement(self, multiparams, params)
  File "/Users/nessad/.virtualenvs/fortunesite/lib/python3.7/site-packages/sqlalchemy/engine/base.py", line 1107, in _execute_clauseelement
    distilled_params,
  File "/Users/nessad/.virtualenvs/fortunesite/lib/python3.7/site-packages/sqlalchemy/engine/base.py", line 1253, in _execute_context
    e, statement, parameters, cursor, context
  File "/Users/nessad/.virtualenvs/fortunesite/lib/python3.7/site-packages/sqlalchemy/engine/base.py", line 1473, in _handle_dbapi_exception
    util.raise_from_cause(sqlalchemy_exception, exc_info)
  File "/Users/nessad/.virtualenvs/fortunesite/lib/python3.7/site-packages/sqlalchemy/util/compat.py", line 398, in raise_from_cause
    reraise(type(exception), exception, tb=exc_tb, cause=cause)
  File "/Users/nessad/.virtualenvs/fortunesite/lib/python3.7/site-packages/sqlalchemy/util/compat.py", line 152, in reraise
    raise value.with_traceback(tb)
  File "/Users/nessad/.virtualenvs/fortunesite/lib/python3.7/site-packages/sqlalchemy/engine/base.py", line 1249, in _execute_context
    cursor, statement, parameters, context
  File "/Users/nessad/.virtualenvs/fortunesite/lib/python3.7/site-packages/sqlalchemy/engine/default.py", line 580, in do_execute
    cursor.execute(statement, parameters)
sqlalchemy.exc.IntegrityError: (sqlite3.IntegrityError) UNIQUE constraint failed: user.username
[SQL: UPDATE user SET username=?, about_me=? WHERE user.id = ?]
[parameters: ('tahmid', 'blahblah', 2)]
(Background on this error at: http://sqlalche.me/e/gkpj)
2019-10-24 15:41:45,790 INFO: FortuneSite startup [in /Users/nessad/Programming/fortunesite/fortunesite/__init__.py:49]
2019-10-24 15:41:52,435 ERROR: Exception on /edit_profile [GET] [in /Users/nessad/.virtualenvs/fortunesite/lib/python3.7/site-packages/flask/app.py:1891]
Traceback (most recent call last):
  File "/Users/nessad/.virtualenvs/fortunesite/lib/python3.7/site-packages/flask/app.py", line 2446, in wsgi_app
    response = self.full_dispatch_request()
  File "/Users/nessad/.virtualenvs/fortunesite/lib/python3.7/site-packages/flask/app.py", line 1951, in full_dispatch_request
    rv = self.handle_user_exception(e)
  File "/Users/nessad/.virtualenvs/fortunesite/lib/python3.7/site-packages/flask/app.py", line 1820, in handle_user_exception
    reraise(exc_type, exc_value, tb)
  File "/Users/nessad/.virtualenvs/fortunesite/lib/python3.7/site-packages/flask/_compat.py", line 39, in reraise
    raise value
  File "/Users/nessad/.virtualenvs/fortunesite/lib/python3.7/site-packages/flask/app.py", line 1949, in full_dispatch_request
    rv = self.dispatch_request()
  File "/Users/nessad/.virtualenvs/fortunesite/lib/python3.7/site-packages/flask/app.py", line 1935, in dispatch_request
    return self.view_functions[rule.endpoint](**req.view_args)
  File "/Users/nessad/.virtualenvs/fortunesite/lib/python3.7/site-packages/flask_login/utils.py", line 261, in decorated_view
    return func(*args, **kwargs)
  File "/Users/nessad/Programming/fortunesite/fortunesite/routes.py", line 94, in edit_profile
    form = EditProfileForm()
  File "/Users/nessad/.virtualenvs/fortunesite/lib/python3.7/site-packages/wtforms/form.py", line 212, in __call__
    return type.__call__(cls, *args, **kwargs)
TypeError: __init__() missing 1 required positional argument: 'original_username'
2019-10-24 15:41:58,546 ERROR: Exception on /edit_profile [GET] [in /Users/nessad/.virtualenvs/fortunesite/lib/python3.7/site-packages/flask/app.py:1891]
Traceback (most recent call last):
  File "/Users/nessad/.virtualenvs/fortunesite/lib/python3.7/site-packages/flask/app.py", line 2446, in wsgi_app
    response = self.full_dispatch_request()
  File "/Users/nessad/.virtualenvs/fortunesite/lib/python3.7/site-packages/flask/app.py", line 1951, in full_dispatch_request
    rv = self.handle_user_exception(e)
  File "/Users/nessad/.virtualenvs/fortunesite/lib/python3.7/site-packages/flask/app.py", line 1820, in handle_user_exception
    reraise(exc_type, exc_value, tb)
  File "/Users/nessad/.virtualenvs/fortunesite/lib/python3.7/site-packages/flask/_compat.py", line 39, in reraise
    raise value
  File "/Users/nessad/.virtualenvs/fortunesite/lib/python3.7/site-packages/flask/app.py", line 1949, in full_dispatch_request
    rv = self.dispatch_request()
  File "/Users/nessad/.virtualenvs/fortunesite/lib/python3.7/site-packages/flask/app.py", line 1935, in dispatch_request
    return self.view_functions[rule.endpoint](**req.view_args)
  File "/Users/nessad/.virtualenvs/fortunesite/lib/python3.7/site-packages/flask_login/utils.py", line 261, in decorated_view
    return func(*args, **kwargs)
  File "/Users/nessad/Programming/fortunesite/fortunesite/routes.py", line 94, in edit_profile
    form = EditProfileForm()
  File "/Users/nessad/.virtualenvs/fortunesite/lib/python3.7/site-packages/wtforms/form.py", line 212, in __call__
    return type.__call__(cls, *args, **kwargs)
TypeError: __init__() missing 1 required positional argument: 'original_username'
